<?xml version="1.0"?>
<robot xmlns:xacro="http://www.ros.org/wiki/xacro"  name="robot">

<material name="white">
        <color rgba="1 1 1 1" />
    </material>

    <material name="orange">
        <color rgba="1 0.3 0.1 1" />
    </material>

    <material name="blue">
        <color rgba="0.2 0.2 1 1" />
    </material>

    <material name="black">
        <color rgba="0 0 0 1" />
    </material>

    <material name="red">
        <color rgba="1 0 0 1" />
    </material>

    <!--Base link-->


    <link name="base_link">
        
    </link>

    <!--Chassis link-->
    
    <joint name="chassis_joiny" type="fixed">
        <parent link="base_link"/>
        <child link="chassis"/>
    </joint>
    
    <link name="chassis">
        <visual>
            <origin xyz="0.0 0.0 0.0"/>
            <geometry>
                <box size="0.2 0.1 0.2"/>
            </geometry>
        </visual>
    </link>

    <!--Left front Wheel -->


    <joint name="left_front_wheel" type="continuous">
        <parent link="base_link"/>
        <child link="Left_wheel"/>
        <origin xyz="0.0 0.175 0.0" rpy="-${pi/2} 0.0 0.0"/>
        <axis xyz="0.0 0.0 1.0"/>
    </joint>

    <link name="Left_wheel">
        <visual>
            <geometry>
                <cylinder radius="0.065" length="0.03"/>
            </geometry>
            <material name="white">
        </visual>
    </link>
</robot>